<mujoco>
  <worldbody><body name="palm_lower" pos="0 0 .1" quat="0 1 0 0">
    <inertial pos="0 0 0" quat="0.497095 0.495942 -0.509424 0.497419" mass="0.237" diaginertia="0.000529322 0.000354076 0.000260868"/>
    <body name="ffmcp_joint" pos="-0.00709525 0.0230578 -0.0187224" quat="1 1 1 -1">
      <inertial pos="0 0 0" quat="0.388585 0.626468 -0.324549 0.592628" mass="0.044" diaginertia="1.47756e-05 1.31982e-05 6.0802e-06"/>
      <joint name="1" range="-0.314 2.23" actuatorfrcrange="-0.95 0.95" axis="0 0 -1"/>
      <body name="ffpip" pos="-0.0122 0.0381 0.0145" quat="1 -1 -1 1">
        <inertial pos="0 0 0" quat="0.709913 0.704273 -0.000363156 0.00475427" mass="0.032" diaginertia="4.7981e-06 4.23406e-06 2.86184e-06"/>
        <joint name="0" range="-1.047 1.047" actuatorfrcrange="-0.95 0.95" axis="0 0 -1"/>
        <body name="ffdip" pos="0.015 0.0143 -0.013" quat="1 1 -1 1">
          <inertial pos="0 0 0" quat="-0.252689 0.659216 0.238844 0.666735" mass="0.037" diaginertia="6.68256e-06 6.24841e-06 5.02002e-06"/>
          <joint name="2" range="-0.506 1.885" actuatorfrcrange="-0.95 0.95" axis="0 0 -1"/>
          <body name="fffingertip" pos="-4.08806e-09 -0.0361 0.0002">
            <inertial pos="0 0 0" quat="0.706755 0.706755 0.0223155 0.0223155" mass="0.016" diaginertia="3.37527e-06 2.863e-06 1.54873e-06"/>
            <joint name="3" range="-0.366 2.042" actuatorfrcrange="-0.95 0.95" axis="0 0 -1"/>
            <body name="fffingertip_panel_base" pos="-0.0123 -0.035 0.0147" quat="0.70710678 0.0 0.70710678 0.0"/></body>
        </body>
      </body>
    </body>
    <body name="mfmcp_joint" pos="-0.00709525 -0.0223922 -0.0187224" quat="1 1 1 -1">
      <inertial pos="0 0 0" quat="0.388585 0.626468 -0.324549 0.592628" mass="0.044" diaginertia="1.47756e-05 1.31982e-05 6.0802e-06"/>
      <joint name="5" range="-0.314 2.23" actuatorfrcrange="-0.95 0.95" axis="0 0 -1"/>
      <body name="mfpip" pos="-0.0122 0.0381 0.0145" quat="1 -1 -1 1">
        <inertial pos="0 0 0" quat="0.709913 0.704273 -0.000363156 0.00475427" mass="0.032" diaginertia="4.7981e-06 4.23406e-06 2.86184e-06"/>
        <joint name="4" range="-1.047 1.047" actuatorfrcrange="-0.95 0.95" axis="0 0 -1"/>
        <body name="mfdip" pos="0.015 0.0143 -0.013" quat="1 1 -1 1">
          <inertial pos="0 0 0" quat="-0.252689 0.659216 0.238844 0.666735" mass="0.037" diaginertia="6.68256e-06 6.24841e-06 5.02002e-06"/>
          <joint name="6" range="-0.506 1.885" actuatorfrcrange="-0.95 0.95" axis="0 0 -1"/>
          <body name="mffingertip" pos="0 -0.0361 0.0002">
            <inertial pos="0 0 0" quat="0.706755 0.706755 0.0223155 0.0223155" mass="0.016" diaginertia="3.37527e-06 2.863e-06 1.54873e-06"/>
            <joint name="7" range="-0.366 2.042" actuatorfrcrange="-0.95 0.95" axis="0 0 -1"/>
            <body name="mffingertip_panel_base" pos="-0.0123 -0.035 0.0147" quat="0.70710678 0.0 0.70710678 0.0"/></body>
        </body>
      </body>
    </body>
    <body name="rfmcp_joint" pos="-0.00709525 -0.0678422 -0.0187224" quat="1 1 1 -1">
      <inertial pos="0 0 0" quat="0.388585 0.626468 -0.324549 0.592628" mass="0.044" diaginertia="1.47756e-05 1.31982e-05 6.0802e-06"/>
      <joint name="9" range="-0.314 2.23" actuatorfrcrange="-0.95 0.95" axis="0 0 -1"/>
      <body name="rfpip" pos="-0.0122 0.0381 0.0145" quat="1 -1 -1 1">
        <inertial pos="0 0 0" quat="0.709913 0.704273 -0.000363156 0.00475427" mass="0.032" diaginertia="4.7981e-06 4.23406e-06 2.86184e-06"/>
        <joint name="8" range="-1.047 1.047" actuatorfrcrange="-0.95 0.95" axis="0 0 -1"/>
        <body name="rfdip" pos="0.015 0.0143 -0.013" quat="1 1 -1 1">
          <inertial pos="0 0 0" quat="-0.252689 0.659216 0.238844 0.666735" mass="0.037" diaginertia="6.68256e-06 6.24841e-06 5.02002e-06"/>
          <joint name="10" range="-0.506 1.885" actuatorfrcrange="-0.95 0.95" axis="0 0 -1"/>
          <body name="rffingertip" pos="0 -0.0361 0.0002">
            <inertial pos="0 0 0" quat="0.706755 0.706755 0.0223155 0.0223155" mass="0.016" diaginertia="3.37527e-06 2.863e-06 1.54873e-06"/>
            <joint name="11" range="-0.366 2.042" actuatorfrcrange="-0.95 0.95" axis="0 0 -1"/>
            <body name="rffingertip_panel_base" pos="-0.0123 -0.035 0.0147" quat="0.70710678 0.0 0.70710678 0.0"/></body>
        </body>
      </body>
    </body>
    <body name="thpip0" pos="-0.0693952 -0.00124224 -0.0216224" quat="1 0 1 0">
      <inertial pos="0 0 0" quat="0.709913 0.704273 -0.000363156 0.00475427" mass="0.032" diaginertia="4.7981e-06 4.23406e-06 2.86184e-06"/>
      <joint name="12" range="-0.349 2.094" actuatorfrcrange="-0.95 0.95" axis="0 0 -1"/>
      <body name="thpip" pos="0 0.0143 -0.013" quat="1 1 -1 1">
        <inertial pos="0 0 0" mass="0.003" diaginertia="5.93e-07 5.49e-07 2.24e-07"/>
        <joint name="13" range="-0.47 2.443" actuatorfrcrange="-0.95 0.95" axis="0 0 -1"/>
        <body name="thdip" pos="0 0.0145 -0.017" quat="1 -1 0 0">
          <inertial pos="0 0 0" quat="0.708624 0.704906 0.00637342 0.0303153" mass="0.038" diaginertia="8.48742e-06 7.67823e-06 3.82835e-06"/>
          <joint name="14" range="-1.2 1.9" actuatorfrcrange="-0.95 0.95" axis="0 0 -1"/>
          <body name="thfingertip" pos="0 0.0466 0.0002" quat="0 0 0 1">
            <inertial pos="0 0 0" quat="0.704307 0.709299 0.006848 -0.0282727" mass="0.049" diaginertia="2.03882e-05 1.98443e-05 4.32049e-06"/>
            <joint name="15" range="-1.34 1.88" actuatorfrcrange="-0.95 0.95" axis="0 0 -1"/>
            <body name="thfingertip_panel_base" pos="-0.0123 -0.045 -0.0147" quat="0.70710678 0.0 0.70710678 0.0"/></body>
        </body>
      </body>
    </body>
  </body>

</worldbody>
</mujoco>
