<?xml version="1.0" ?>
<robot name="converted_robot">
  <link name="world"/>
  <joint name="base_joint" type="fixed">
    <parent link="world"/>
    <child link="palm_lower"/>
    <origin xyz="0 0 .1" rpy="3.141592653589793 0.0 0.0"/>
  </joint>
  <link name="palm_lower"/>
  <link name="ffmcp_joint"/>
  <link name="ffpip"/>
  <link name="ffdip"/>
  <link name="fffingertip"/>
  <link name="fffingertip_panel_base"/>
  <joint name="fffingertip_panel_base_joint" type="fixed">
    <origin xyz="-0.0123 -0.035 0.0147" rpy="-0.0 1.5707963267948966 0.0"/>
    <parent link="fffingertip"/>
    <child link="fffingertip_panel_base"/>
  </joint>
  <link name="mfmcp_joint"/>
  <link name="mfpip"/>
  <link name="mfdip"/>
  <link name="mffingertip"/>
  <link name="mffingertip_panel_base"/>
  <joint name="mffingertip_panel_base_joint" type="fixed">
    <origin xyz="-0.0123 -0.035 0.0147" rpy="-0.0 1.5707963267948966 0.0"/>
    <parent link="mffingertip"/>
    <child link="mffingertip_panel_base"/>
  </joint>
  <link name="rfmcp_joint"/>
  <link name="rfpip"/>
  <link name="rfdip"/>
  <link name="rffingertip"/>
  <link name="rffingertip_panel_base"/>
  <joint name="rffingertip_panel_base_joint" type="fixed">
    <origin xyz="-0.0123 -0.035 0.0147" rpy="-0.0 1.5707963267948966 0.0"/>
    <parent link="rffingertip"/>
    <child link="rffingertip_panel_base"/>
  </joint>
  <link name="thpip0"/>
  <link name="thpip"/>
  <link name="thdip"/>
  <link name="thfingertip"/>
  <link name="thfingertip_panel_base"/>
  <joint name="thfingertip_panel_base_joint" type="fixed">
    <origin xyz="-0.0123 -0.045 -0.0147" rpy="-0.0 1.5707963267948966 0.0"/>
    <parent link="thfingertip"/>
    <child link="thfingertip_panel_base"/>
  </joint>
  <joint name="1" type="revolute">
    <origin xyz="-0.00709525 0.0230578 -0.0187224" rpy="1.5707963267948966 1.5707963267948966 0.0"/>
    <parent link="palm_lower"/>
    <child link="ffmcp_joint"/>
    <axis xyz="0 0 -1"/>
    <limit effort="30" velocity="1.0" lower="-0.314" upper="2.23"/>
  </joint>
  <joint name="0" type="revolute">
    <origin xyz="-0.0122 0.0381 0.0145" rpy="-1.5707963267948966 0.0 1.5707963267948966"/>
    <parent link="ffmcp_joint"/>
    <child link="ffpip"/>
    <axis xyz="0 0 -1"/>
    <limit effort="30" velocity="1.0" lower="-1.047" upper="1.047"/>
  </joint>
  <joint name="2" type="revolute">
    <origin xyz="0.015 0.0143 -0.013" rpy="1.5707963267948966 -1.5707963267948966 0.0"/>
    <parent link="ffpip"/>
    <child link="ffdip"/>
    <axis xyz="0 0 -1"/>
    <limit effort="30" velocity="1.0" lower="-0.506" upper="1.885"/>
  </joint>
  <joint name="3" type="revolute">
    <origin xyz="-4.08806e-09 -0.0361 0.0002" rpy="0 0 0"/>
    <parent link="ffdip"/>
    <child link="fffingertip"/>
    <axis xyz="0 0 -1"/>
    <limit effort="30" velocity="1.0" lower="-0.366" upper="2.042"/>
  </joint>
  <joint name="5" type="revolute">
    <origin xyz="-0.00709525 -0.0223922 -0.0187224" rpy="1.5707963267948966 1.5707963267948966 0.0"/>
    <parent link="palm_lower"/>
    <child link="mfmcp_joint"/>
    <axis xyz="0 0 -1"/>
    <limit effort="30" velocity="1.0" lower="-0.314" upper="2.23"/>
  </joint>
  <joint name="4" type="revolute">
    <origin xyz="-0.0122 0.0381 0.0145" rpy="-1.5707963267948966 0.0 1.5707963267948966"/>
    <parent link="mfmcp_joint"/>
    <child link="mfpip"/>
    <axis xyz="0 0 -1"/>
    <limit effort="30" velocity="1.0" lower="-1.047" upper="1.047"/>
  </joint>
  <joint name="6" type="revolute">
    <origin xyz="0.015 0.0143 -0.013" rpy="1.5707963267948966 -1.5707963267948966 0.0"/>
    <parent link="mfpip"/>
    <child link="mfdip"/>
    <axis xyz="0 0 -1"/>
    <limit effort="30" velocity="1.0" lower="-0.506" upper="1.885"/>
  </joint>
  <joint name="7" type="revolute">
    <origin xyz="0 -0.0361 0.0002" rpy="0 0 0"/>
    <parent link="mfdip"/>
    <child link="mffingertip"/>
    <axis xyz="0 0 -1"/>
    <limit effort="30" velocity="1.0" lower="-0.366" upper="2.042"/>
  </joint>
  <joint name="9" type="revolute">
    <origin xyz="-0.00709525 -0.0678422 -0.0187224" rpy="1.5707963267948966 1.5707963267948966 0.0"/>
    <parent link="palm_lower"/>
    <child link="rfmcp_joint"/>
    <axis xyz="0 0 -1"/>
    <limit effort="30" velocity="1.0" lower="-0.314" upper="2.23"/>
  </joint>
  <joint name="8" type="revolute">
    <origin xyz="-0.0122 0.0381 0.0145" rpy="-1.5707963267948966 0.0 1.5707963267948966"/>
    <parent link="rfmcp_joint"/>
    <child link="rfpip"/>
    <axis xyz="0 0 -1"/>
    <limit effort="30" velocity="1.0" lower="-1.047" upper="1.047"/>
  </joint>
  <joint name="10" type="revolute">
    <origin xyz="0.015 0.0143 -0.013" rpy="1.5707963267948966 -1.5707963267948966 0.0"/>
    <parent link="rfpip"/>
    <child link="rfdip"/>
    <axis xyz="0 0 -1"/>
    <limit effort="30" velocity="1.0" lower="-0.506" upper="1.885"/>
  </joint>
  <joint name="11" type="revolute">
    <origin xyz="0 -0.0361 0.0002" rpy="0 0 0"/>
    <parent link="rfdip"/>
    <child link="rffingertip"/>
    <axis xyz="0 0 -1"/>
    <limit effort="30" velocity="1.0" lower="-0.366" upper="2.042"/>
  </joint>
  <joint name="12" type="revolute">
    <origin xyz="-0.0693952 -0.00124224 -0.0216224" rpy="-0.0 1.5707963057214722 0.0"/>
    <parent link="palm_lower"/>
    <child link="thpip0"/>
    <axis xyz="0 0 -1"/>
    <limit effort="30" velocity="1.0" lower="-0.349" upper="2.094"/>
  </joint>
  <joint name="13" type="revolute">
    <origin xyz="0 0.0143 -0.013" rpy="1.5707963267948966 -1.5707963267948966 0.0"/>
    <parent link="thpip0"/>
    <child link="thpip"/>
    <axis xyz="0 0 -1"/>
    <limit effort="30" velocity="1.0" lower="-0.47" upper="2.443"/>
  </joint>
  <joint name="14" type="revolute">
    <origin xyz="0 0.0145 -0.017" rpy="-1.5707963267948966 0.0 0.0"/>
    <parent link="thpip"/>
    <child link="thdip"/>
    <axis xyz="0 0 -1"/>
    <limit effort="30" velocity="1.0" lower="-1.2" upper="1.9"/>
  </joint>
  <joint name="15" type="revolute">
    <origin xyz="0 0.0466 0.0002" rpy="0.0 0.0 3.141592653589793"/>
    <parent link="thdip"/>
    <child link="thfingertip"/>
    <axis xyz="0 0 -1"/>
    <limit effort="30" velocity="1.0" lower="-1.34" upper="1.88"/>
  </joint>
</robot>