<mujocoinclude model="right leap hand">

  <body name="palm_lower" childclass="right_leap" pos="0 0 .1" quat="0 1 0 0">
    <inertial pos="0 0 0" quat="0.497095 0.495942 -0.509424 0.497419" mass="0.237" diaginertia="0.000529322 0.000354076 0.000260868" />
    <geom pos="-0.0200952 0.0257578 -0.0347224" quat="1 0 0 0" mesh="palm_lower" class="visual" />
    <geom pos="-0.0200952 0.0257578 -0.0347224" quat="1 0 0 0" mesh="palm_lower" class="collision" />
    <body name="ffmcp_joint" pos="-0.00709525 0.0230578 -0.0187224" quat="1 1 1 -1">
      <inertial pos="0 0 0" quat="0.388585 0.626468 -0.324549 0.592628" mass="0.044" diaginertia="1.47756e-05 1.31982e-05 6.0802e-06" />
      <joint name="1" range="-0.314 2.23" actuatorfrcrange="-0.95 0.95" />
      <geom pos="0.0084069 0.00776624 0.0146574" quat="1 0 0 0" mesh="mcp_joint" class="visual" />
      <geom pos="0.0084069 0.00776624 0.0146574" quat="1 0 0 0" mesh="mcp_joint" class="collision" />
      <body name="ffpip" pos="-0.0122 0.0381 0.0145" quat="1 -1 -1 1">
        <inertial pos="0 0 0" quat="0.709913 0.704273 -0.000363156 0.00475427" mass="0.032" diaginertia="4.7981e-06 4.23406e-06 2.86184e-06" />
        <joint name="0" range="-1.047 1.047" actuatorfrcrange="-0.95 0.95" />
        <geom pos="0.00964336 0.0003 0.000784034" quat="1 -1 -1 -1" mesh="pip" class="visual" />
        <geom pos="0.00964336 0.0003 0.000784034" quat="1 -1 -1 -1" mesh="pip" class="collision" />
        <body name="ffdip" pos="0.015 0.0143 -0.013" quat="1 1 -1 1">
          <inertial pos="0 0 0" quat="-0.252689 0.659216 0.238844 0.666735" mass="0.037" diaginertia="6.68256e-06 6.24841e-06 5.02002e-06" />
          <joint name="2" range="-0.506 1.885" actuatorfrcrange="-0.95 0.95" />
          <geom pos="0.0211334 -0.00843212 0.00978509" quat="0 -1 0 0" mesh="dip" class="visual" />
          <geom pos="0.0211334 -0.00843212 0.00978509" quat="0 -1 0 0" mesh="dip" class="collision" />
          <body name="fffingertip" pos="-4.08806e-09 -0.0361 0.0002">
            <inertial pos="0 0 0" quat="0.706755 0.706755 0.0223155 0.0223155" mass="0.016" diaginertia="3.37527e-06 2.863e-06 1.54873e-06" />
            <joint name="3" range="-0.366 2.042" actuatorfrcrange="-0.95 0.95" />
            <geom pos="0.0132864 -0.00611424 0.0145" quat="0 1 0 0" mesh="fingertip" class="visual" />
            <geom pos="0.0132864 -0.00611424 0.0145" quat="0 1 0 0" mesh="fingertip" class="collision" />
            <body name="fffingertip_panel_base" pos="-0.0123 -0.035 0.0147" quat="0.70710678 0.0 0.70710678 0.0">
              <body name="fffingertip_T_r0c0" pos="-0.0045000000000000005 -0.0045000000000000005 0.0">
                <geom type="sphere" size="0.001" rgba="0.2 0.2 0.7 0.5" class="DC_Taxel" />
                <inertial mass="1e-05" diaginertia="1e-06 1e-06 1e-06" pos="0 0 0" />
                <joint type="slide" stiffness="1000.0" damping="0.0001" axis="0 0 1" name="fffingertip_J_r0c0" range="-0.001 0.001" />
                <site name="fffingertip_S_r0c0" pos="0 0 0" class="D_Array" />
              </body>
              <body name="fffingertip_T_r0c1" pos="-0.0015000000000000005 -0.0045000000000000005 0.0">
                <geom type="sphere" size="0.001" rgba="0.2 0.2 0.7 0.5" class="DC_Taxel" />
                <inertial mass="1e-05" diaginertia="1e-06 1e-06 1e-06" pos="0 0 0" />
                <joint type="slide" stiffness="1000.0" damping="0.0001" axis="0 0 1" name="fffingertip_J_r0c1" range="-0.001 0.001" />
                <site name="fffingertip_S_r0c1" pos="0 0 0" class="D_Array" />
              </body>
              <body name="fffingertip_T_r0c2" pos="0.0014999999999999996 -0.0045000000000000005 0.0">
                <geom type="sphere" size="0.001" rgba="0.2 0.2 0.7 0.5" class="DC_Taxel" />
                <inertial mass="1e-05" diaginertia="1e-06 1e-06 1e-06" pos="0 0 0" />
                <joint type="slide" stiffness="1000.0" damping="0.0001" axis="0 0 1" name="fffingertip_J_r0c2" range="-0.001 0.001" />
                <site name="fffingertip_S_r0c2" pos="0 0 0" class="D_Array" />
              </body>
              <body name="fffingertip_T_r0c3" pos="0.0045000000000000005 -0.0045000000000000005 0.0">
                <geom type="sphere" size="0.001" rgba="0.2 0.2 0.7 0.5" class="DC_Taxel" />
                <inertial mass="1e-05" diaginertia="1e-06 1e-06 1e-06" pos="0 0 0" />
                <joint type="slide" stiffness="1000.0" damping="0.0001" axis="0 0 1" name="fffingertip_J_r0c3" range="-0.001 0.001" />
                <site name="fffingertip_S_r0c3" pos="0 0 0" class="D_Array" />
              </body>
              <body name="fffingertip_T_r1c0" pos="-0.0045000000000000005 -0.0015000000000000005 0.0">
                <geom type="sphere" size="0.001" rgba="0.2 0.2 0.7 0.5" class="DC_Taxel" />
                <inertial mass="1e-05" diaginertia="1e-06 1e-06 1e-06" pos="0 0 0" />
                <joint type="slide" stiffness="1000.0" damping="0.0001" axis="0 0 1" name="fffingertip_J_r1c0" range="-0.001 0.001" />
                <site name="fffingertip_S_r1c0" pos="0 0 0" class="D_Array" />
              </body>
              <body name="fffingertip_T_r1c1" pos="-0.0015000000000000005 -0.0015000000000000005 0.0">
                <geom type="sphere" size="0.001" rgba="0.2 0.2 0.7 0.5" class="DC_Taxel" />
                <inertial mass="1e-05" diaginertia="1e-06 1e-06 1e-06" pos="0 0 0" />
                <joint type="slide" stiffness="1000.0" damping="0.0001" axis="0 0 1" name="fffingertip_J_r1c1" range="-0.001 0.001" />
                <site name="fffingertip_S_r1c1" pos="0 0 0" class="D_Array" />
              </body>
              <body name="fffingertip_T_r1c2" pos="0.0014999999999999996 -0.0015000000000000005 0.0">
                <geom type="sphere" size="0.001" rgba="0.2 0.2 0.7 0.5" class="DC_Taxel" />
                <inertial mass="1e-05" diaginertia="1e-06 1e-06 1e-06" pos="0 0 0" />
                <joint type="slide" stiffness="1000.0" damping="0.0001" axis="0 0 1" name="fffingertip_J_r1c2" range="-0.001 0.001" />
                <site name="fffingertip_S_r1c2" pos="0 0 0" class="D_Array" />
              </body>
              <body name="fffingertip_T_r1c3" pos="0.0045000000000000005 -0.0015000000000000005 0.0">
                <geom type="sphere" size="0.001" rgba="0.2 0.2 0.7 0.5" class="DC_Taxel" />
                <inertial mass="1e-05" diaginertia="1e-06 1e-06 1e-06" pos="0 0 0" />
                <joint type="slide" stiffness="1000.0" damping="0.0001" axis="0 0 1" name="fffingertip_J_r1c3" range="-0.001 0.001" />
                <site name="fffingertip_S_r1c3" pos="0 0 0" class="D_Array" />
              </body>
              <body name="fffingertip_T_r2c0" pos="-0.0045000000000000005 0.0014999999999999996 0.0">
                <geom type="sphere" size="0.001" rgba="0.2 0.2 0.7 0.5" class="DC_Taxel" />
                <inertial mass="1e-05" diaginertia="1e-06 1e-06 1e-06" pos="0 0 0" />
                <joint type="slide" stiffness="1000.0" damping="0.0001" axis="0 0 1" name="fffingertip_J_r2c0" range="-0.001 0.001" />
                <site name="fffingertip_S_r2c0" pos="0 0 0" class="D_Array" />
              </body>
              <body name="fffingertip_T_r2c1" pos="-0.0015000000000000005 0.0014999999999999996 0.0">
                <geom type="sphere" size="0.001" rgba="0.2 0.2 0.7 0.5" class="DC_Taxel" />
                <inertial mass="1e-05" diaginertia="1e-06 1e-06 1e-06" pos="0 0 0" />
                <joint type="slide" stiffness="1000.0" damping="0.0001" axis="0 0 1" name="fffingertip_J_r2c1" range="-0.001 0.001" />
                <site name="fffingertip_S_r2c1" pos="0 0 0" class="D_Array" />
              </body>
              <body name="fffingertip_T_r2c2" pos="0.0014999999999999996 0.0014999999999999996 0.0">
                <geom type="sphere" size="0.001" rgba="0.2 0.2 0.7 0.5" class="DC_Taxel" />
                <inertial mass="1e-05" diaginertia="1e-06 1e-06 1e-06" pos="0 0 0" />
                <joint type="slide" stiffness="1000.0" damping="0.0001" axis="0 0 1" name="fffingertip_J_r2c2" range="-0.001 0.001" />
                <site name="fffingertip_S_r2c2" pos="0 0 0" class="D_Array" />
              </body>
              <body name="fffingertip_T_r2c3" pos="0.0045000000000000005 0.0014999999999999996 0.0">
                <geom type="sphere" size="0.001" rgba="0.2 0.2 0.7 0.5" class="DC_Taxel" />
                <inertial mass="1e-05" diaginertia="1e-06 1e-06 1e-06" pos="0 0 0" />
                <joint type="slide" stiffness="1000.0" damping="0.0001" axis="0 0 1" name="fffingertip_J_r2c3" range="-0.001 0.001" />
                <site name="fffingertip_S_r2c3" pos="0 0 0" class="D_Array" />
              </body>
              <body name="fffingertip_T_r3c0" pos="-0.0045000000000000005 0.0045000000000000005 0.0">
                <geom type="sphere" size="0.001" rgba="0.2 0.2 0.7 0.5" class="DC_Taxel" />
                <inertial mass="1e-05" diaginertia="1e-06 1e-06 1e-06" pos="0 0 0" />
                <joint type="slide" stiffness="1000.0" damping="0.0001" axis="0 0 1" name="fffingertip_J_r3c0" range="-0.001 0.001" />
                <site name="fffingertip_S_r3c0" pos="0 0 0" class="D_Array" />
              </body>
              <body name="fffingertip_T_r3c1" pos="-0.0015000000000000005 0.0045000000000000005 0.0">
                <geom type="sphere" size="0.001" rgba="0.2 0.2 0.7 0.5" class="DC_Taxel" />
                <inertial mass="1e-05" diaginertia="1e-06 1e-06 1e-06" pos="0 0 0" />
                <joint type="slide" stiffness="1000.0" damping="0.0001" axis="0 0 1" name="fffingertip_J_r3c1" range="-0.001 0.001" />
                <site name="fffingertip_S_r3c1" pos="0 0 0" class="D_Array" />
              </body>
              <body name="fffingertip_T_r3c2" pos="0.0014999999999999996 0.0045000000000000005 0.0">
                <geom type="sphere" size="0.001" rgba="0.2 0.2 0.7 0.5" class="DC_Taxel" />
                <inertial mass="1e-05" diaginertia="1e-06 1e-06 1e-06" pos="0 0 0" />
                <joint type="slide" stiffness="1000.0" damping="0.0001" axis="0 0 1" name="fffingertip_J_r3c2" range="-0.001 0.001" />
                <site name="fffingertip_S_r3c2" pos="0 0 0" class="D_Array" />
              </body>
              <body name="fffingertip_T_r3c3" pos="0.0045000000000000005 0.0045000000000000005 0.0">
                <geom type="sphere" size="0.001" rgba="0.2 0.2 0.7 0.5" class="DC_Taxel" />
                <inertial mass="1e-05" diaginertia="1e-06 1e-06 1e-06" pos="0 0 0" />
                <joint type="slide" stiffness="1000.0" damping="0.0001" axis="0 0 1" name="fffingertip_J_r3c3" range="-0.001 0.001" />
                <site name="fffingertip_S_r3c3" pos="0 0 0" class="D_Array" />
              </body>
            </body>
          </body>
        </body>
      </body>
    </body>
    <body name="mfmcp_joint" pos="-0.00709525 -0.0223922 -0.0187224" quat="1 1 1 -1">
      <inertial pos="0 0 0" quat="0.388585 0.626468 -0.324549 0.592628" mass="0.044" diaginertia="1.47756e-05 1.31982e-05 6.0802e-06" />
      <joint name="5" range="-0.314 2.23" actuatorfrcrange="-0.95 0.95" />
      <geom pos="0.0084069 0.00776624 0.0146574" quat="1 0 0 0" mesh="mcp_joint" class="visual" />
      <geom pos="0.0084069 0.00776624 0.0146574" quat="1 0 0 0" mesh="mcp_joint" class="collision" />
      <body name="mfpip" pos="-0.0122 0.0381 0.0145" quat="1 -1 -1 1">
        <inertial pos="0 0 0" quat="0.709913 0.704273 -0.000363156 0.00475427" mass="0.032" diaginertia="4.7981e-06 4.23406e-06 2.86184e-06" />
        <joint name="4" range="-1.047 1.047" actuatorfrcrange="-0.95 0.95" />
        <geom pos="0.00964336 0.0003 0.000784034" quat="1 -1 -1 -1" mesh="pip" class="visual" />
        <geom pos="0.00964336 0.0003 0.000784034" quat="1 -1 -1 -1" mesh="pip" class="collision" />
        <body name="mfdip" pos="0.015 0.0143 -0.013" quat="1 1 -1 1">
          <inertial pos="0 0 0" quat="-0.252689 0.659216 0.238844 0.666735" mass="0.037" diaginertia="6.68256e-06 6.24841e-06 5.02002e-06" />
          <joint name="6" range="-0.506 1.885" actuatorfrcrange="-0.95 0.95" />
          <geom pos="0.0211334 -0.00843212 0.00978509" quat="0 -1 0 0" mesh="dip" class="visual" />
          <geom pos="0.0211334 -0.00843212 0.00978509" quat="0 -1 0 0" mesh="dip" class="collision" />
          <body name="mffingertip" pos="0 -0.0361 0.0002">
            <inertial pos="0 0 0" quat="0.706755 0.706755 0.0223155 0.0223155" mass="0.016" diaginertia="3.37527e-06 2.863e-06 1.54873e-06" />
            <joint name="7" range="-0.366 2.042" actuatorfrcrange="-0.95 0.95" />
            <geom pos="0.0132864 -0.00611424 0.0145" quat="0 1 0 0" mesh="fingertip" class="visual" />
            <geom pos="0.0132864 -0.00611424 0.0145" quat="0 1 0 0" mesh="fingertip" class="collision" />
            <body name="mffingertip_panel_base" pos="-0.0123 -0.035 0.0147" quat="0.70710678 0.0 0.70710678 0.0">
              <body name="mffingertip_T_r0c0" pos="-0.0045000000000000005 -0.0045000000000000005 0.0">
                <geom type="sphere" size="0.001" rgba="0.2 0.2 0.7 0.5" class="DC_Taxel" />
                <inertial mass="1e-05" diaginertia="1e-06 1e-06 1e-06" pos="0 0 0" />
                <joint type="slide" stiffness="1000.0" damping="0.0001" axis="0 0 1" name="mffingertip_J_r0c0" range="-0.001 0.001" />
                <site name="mffingertip_S_r0c0" pos="0 0 0" class="D_Array" />
              </body>
              <body name="mffingertip_T_r0c1" pos="-0.0015000000000000005 -0.0045000000000000005 0.0">
                <geom type="sphere" size="0.001" rgba="0.2 0.2 0.7 0.5" class="DC_Taxel" />
                <inertial mass="1e-05" diaginertia="1e-06 1e-06 1e-06" pos="0 0 0" />
                <joint type="slide" stiffness="1000.0" damping="0.0001" axis="0 0 1" name="mffingertip_J_r0c1" range="-0.001 0.001" />
                <site name="mffingertip_S_r0c1" pos="0 0 0" class="D_Array" />
              </body>
              <body name="mffingertip_T_r0c2" pos="0.0014999999999999996 -0.0045000000000000005 0.0">
                <geom type="sphere" size="0.001" rgba="0.2 0.2 0.7 0.5" class="DC_Taxel" />
                <inertial mass="1e-05" diaginertia="1e-06 1e-06 1e-06" pos="0 0 0" />
                <joint type="slide" stiffness="1000.0" damping="0.0001" axis="0 0 1" name="mffingertip_J_r0c2" range="-0.001 0.001" />
                <site name="mffingertip_S_r0c2" pos="0 0 0" class="D_Array" />
              </body>
              <body name="mffingertip_T_r0c3" pos="0.0045000000000000005 -0.0045000000000000005 0.0">
                <geom type="sphere" size="0.001" rgba="0.2 0.2 0.7 0.5" class="DC_Taxel" />
                <inertial mass="1e-05" diaginertia="1e-06 1e-06 1e-06" pos="0 0 0" />
                <joint type="slide" stiffness="1000.0" damping="0.0001" axis="0 0 1" name="mffingertip_J_r0c3" range="-0.001 0.001" />
                <site name="mffingertip_S_r0c3" pos="0 0 0" class="D_Array" />
              </body>
              <body name="mffingertip_T_r1c0" pos="-0.0045000000000000005 -0.0015000000000000005 0.0">
                <geom type="sphere" size="0.001" rgba="0.2 0.2 0.7 0.5" class="DC_Taxel" />
                <inertial mass="1e-05" diaginertia="1e-06 1e-06 1e-06" pos="0 0 0" />
                <joint type="slide" stiffness="1000.0" damping="0.0001" axis="0 0 1" name="mffingertip_J_r1c0" range="-0.001 0.001" />
                <site name="mffingertip_S_r1c0" pos="0 0 0" class="D_Array" />
              </body>
              <body name="mffingertip_T_r1c1" pos="-0.0015000000000000005 -0.0015000000000000005 0.0">
                <geom type="sphere" size="0.001" rgba="0.2 0.2 0.7 0.5" class="DC_Taxel" />
                <inertial mass="1e-05" diaginertia="1e-06 1e-06 1e-06" pos="0 0 0" />
                <joint type="slide" stiffness="1000.0" damping="0.0001" axis="0 0 1" name="mffingertip_J_r1c1" range="-0.001 0.001" />
                <site name="mffingertip_S_r1c1" pos="0 0 0" class="D_Array" />
              </body>
              <body name="mffingertip_T_r1c2" pos="0.0014999999999999996 -0.0015000000000000005 0.0">
                <geom type="sphere" size="0.001" rgba="0.2 0.2 0.7 0.5" class="DC_Taxel" />
                <inertial mass="1e-05" diaginertia="1e-06 1e-06 1e-06" pos="0 0 0" />
                <joint type="slide" stiffness="1000.0" damping="0.0001" axis="0 0 1" name="mffingertip_J_r1c2" range="-0.001 0.001" />
                <site name="mffingertip_S_r1c2" pos="0 0 0" class="D_Array" />
              </body>
              <body name="mffingertip_T_r1c3" pos="0.0045000000000000005 -0.0015000000000000005 0.0">
                <geom type="sphere" size="0.001" rgba="0.2 0.2 0.7 0.5" class="DC_Taxel" />
                <inertial mass="1e-05" diaginertia="1e-06 1e-06 1e-06" pos="0 0 0" />
                <joint type="slide" stiffness="1000.0" damping="0.0001" axis="0 0 1" name="mffingertip_J_r1c3" range="-0.001 0.001" />
                <site name="mffingertip_S_r1c3" pos="0 0 0" class="D_Array" />
              </body>
              <body name="mffingertip_T_r2c0" pos="-0.0045000000000000005 0.0014999999999999996 0.0">
                <geom type="sphere" size="0.001" rgba="0.2 0.2 0.7 0.5" class="DC_Taxel" />
                <inertial mass="1e-05" diaginertia="1e-06 1e-06 1e-06" pos="0 0 0" />
                <joint type="slide" stiffness="1000.0" damping="0.0001" axis="0 0 1" name="mffingertip_J_r2c0" range="-0.001 0.001" />
                <site name="mffingertip_S_r2c0" pos="0 0 0" class="D_Array" />
              </body>
              <body name="mffingertip_T_r2c1" pos="-0.0015000000000000005 0.0014999999999999996 0.0">
                <geom type="sphere" size="0.001" rgba="0.2 0.2 0.7 0.5" class="DC_Taxel" />
                <inertial mass="1e-05" diaginertia="1e-06 1e-06 1e-06" pos="0 0 0" />
                <joint type="slide" stiffness="1000.0" damping="0.0001" axis="0 0 1" name="mffingertip_J_r2c1" range="-0.001 0.001" />
                <site name="mffingertip_S_r2c1" pos="0 0 0" class="D_Array" />
              </body>
              <body name="mffingertip_T_r2c2" pos="0.0014999999999999996 0.0014999999999999996 0.0">
                <geom type="sphere" size="0.001" rgba="0.2 0.2 0.7 0.5" class="DC_Taxel" />
                <inertial mass="1e-05" diaginertia="1e-06 1e-06 1e-06" pos="0 0 0" />
                <joint type="slide" stiffness="1000.0" damping="0.0001" axis="0 0 1" name="mffingertip_J_r2c2" range="-0.001 0.001" />
                <site name="mffingertip_S_r2c2" pos="0 0 0" class="D_Array" />
              </body>
              <body name="mffingertip_T_r2c3" pos="0.0045000000000000005 0.0014999999999999996 0.0">
                <geom type="sphere" size="0.001" rgba="0.2 0.2 0.7 0.5" class="DC_Taxel" />
                <inertial mass="1e-05" diaginertia="1e-06 1e-06 1e-06" pos="0 0 0" />
                <joint type="slide" stiffness="1000.0" damping="0.0001" axis="0 0 1" name="mffingertip_J_r2c3" range="-0.001 0.001" />
                <site name="mffingertip_S_r2c3" pos="0 0 0" class="D_Array" />
              </body>
              <body name="mffingertip_T_r3c0" pos="-0.0045000000000000005 0.0045000000000000005 0.0">
                <geom type="sphere" size="0.001" rgba="0.2 0.2 0.7 0.5" class="DC_Taxel" />
                <inertial mass="1e-05" diaginertia="1e-06 1e-06 1e-06" pos="0 0 0" />
                <joint type="slide" stiffness="1000.0" damping="0.0001" axis="0 0 1" name="mffingertip_J_r3c0" range="-0.001 0.001" />
                <site name="mffingertip_S_r3c0" pos="0 0 0" class="D_Array" />
              </body>
              <body name="mffingertip_T_r3c1" pos="-0.0015000000000000005 0.0045000000000000005 0.0">
                <geom type="sphere" size="0.001" rgba="0.2 0.2 0.7 0.5" class="DC_Taxel" />
                <inertial mass="1e-05" diaginertia="1e-06 1e-06 1e-06" pos="0 0 0" />
                <joint type="slide" stiffness="1000.0" damping="0.0001" axis="0 0 1" name="mffingertip_J_r3c1" range="-0.001 0.001" />
                <site name="mffingertip_S_r3c1" pos="0 0 0" class="D_Array" />
              </body>
              <body name="mffingertip_T_r3c2" pos="0.0014999999999999996 0.0045000000000000005 0.0">
                <geom type="sphere" size="0.001" rgba="0.2 0.2 0.7 0.5" class="DC_Taxel" />
                <inertial mass="1e-05" diaginertia="1e-06 1e-06 1e-06" pos="0 0 0" />
                <joint type="slide" stiffness="1000.0" damping="0.0001" axis="0 0 1" name="mffingertip_J_r3c2" range="-0.001 0.001" />
                <site name="mffingertip_S_r3c2" pos="0 0 0" class="D_Array" />
              </body>
              <body name="mffingertip_T_r3c3" pos="0.0045000000000000005 0.0045000000000000005 0.0">
                <geom type="sphere" size="0.001" rgba="0.2 0.2 0.7 0.5" class="DC_Taxel" />
                <inertial mass="1e-05" diaginertia="1e-06 1e-06 1e-06" pos="0 0 0" />
                <joint type="slide" stiffness="1000.0" damping="0.0001" axis="0 0 1" name="mffingertip_J_r3c3" range="-0.001 0.001" />
                <site name="mffingertip_S_r3c3" pos="0 0 0" class="D_Array" />
              </body>
            </body>
          </body>
        </body>
      </body>
    </body>
    <body name="rfmcp_joint" pos="-0.00709525 -0.0678422 -0.0187224" quat="1 1 1 -1">
      <inertial pos="0 0 0" quat="0.388585 0.626468 -0.324549 0.592628" mass="0.044" diaginertia="1.47756e-05 1.31982e-05 6.0802e-06" />
      <joint name="9" range="-0.314 2.23" actuatorfrcrange="-0.95 0.95" />
      <geom pos="0.0084069 0.00776624 0.0146574" quat="1 0 0 0" mesh="mcp_joint" class="visual" />
      <geom pos="0.0084069 0.00776624 0.0146574" quat="1 0 0 0" mesh="mcp_joint" class="collision" />
      <body name="rfpip" pos="-0.0122 0.0381 0.0145" quat="1 -1 -1 1">
        <inertial pos="0 0 0" quat="0.709913 0.704273 -0.000363156 0.00475427" mass="0.032" diaginertia="4.7981e-06 4.23406e-06 2.86184e-06" />
        <joint name="8" range="-1.047 1.047" actuatorfrcrange="-0.95 0.95" />
        <geom pos="0.00964336 0.0003 0.000784034" quat="1 -1 -1 -1" mesh="pip" class="visual" />
        <geom pos="0.00964336 0.0003 0.000784034" quat="1 -1 -1 -1" mesh="pip" class="collision" />
        <body name="rfdip" pos="0.015 0.0143 -0.013" quat="1 1 -1 1">
          <inertial pos="0 0 0" quat="-0.252689 0.659216 0.238844 0.666735" mass="0.037" diaginertia="6.68256e-06 6.24841e-06 5.02002e-06" />
          <joint name="10" range="-0.506 1.885" actuatorfrcrange="-0.95 0.95" />
          <geom pos="0.0211334 -0.00843212 0.00978509" quat="0 -1 0 0" mesh="dip" class="visual" />
          <geom pos="0.0211334 -0.00843212 0.00978509" quat="0 -1 0 0" mesh="dip" class="collision" />
          <body name="rffingertip" pos="0 -0.0361 0.0002">
            <inertial pos="0 0 0" quat="0.706755 0.706755 0.0223155 0.0223155" mass="0.016" diaginertia="3.37527e-06 2.863e-06 1.54873e-06" />
            <joint name="11" range="-0.366 2.042" actuatorfrcrange="-0.95 0.95" />
            <geom pos="0.0132864 -0.00611424 0.0145" quat="0 1 0 0" mesh="fingertip" class="visual" />
            <geom pos="0.0132864 -0.00611424 0.0145" quat="0 1 0 0" mesh="fingertip" class="collision" />
            <body name="rffingertip_panel_base" pos="-0.0123 -0.035 0.0147" quat="0.70710678 0.0 0.70710678 0.0">
              <body name="rffingertip_T_r0c0" pos="-0.0045000000000000005 -0.0045000000000000005 0.0">
                <geom type="sphere" size="0.001" rgba="0.2 0.2 0.7 0.5" class="DC_Taxel" />
                <inertial mass="1e-05" diaginertia="1e-06 1e-06 1e-06" pos="0 0 0" />
                <joint type="slide" stiffness="1000.0" damping="0.0001" axis="0 0 1" name="rffingertip_J_r0c0" range="-0.001 0.001" />
                <site name="rffingertip_S_r0c0" pos="0 0 0" class="D_Array" />
              </body>
              <body name="rffingertip_T_r0c1" pos="-0.0015000000000000005 -0.0045000000000000005 0.0">
                <geom type="sphere" size="0.001" rgba="0.2 0.2 0.7 0.5" class="DC_Taxel" />
                <inertial mass="1e-05" diaginertia="1e-06 1e-06 1e-06" pos="0 0 0" />
                <joint type="slide" stiffness="1000.0" damping="0.0001" axis="0 0 1" name="rffingertip_J_r0c1" range="-0.001 0.001" />
                <site name="rffingertip_S_r0c1" pos="0 0 0" class="D_Array" />
              </body>
              <body name="rffingertip_T_r0c2" pos="0.0014999999999999996 -0.0045000000000000005 0.0">
                <geom type="sphere" size="0.001" rgba="0.2 0.2 0.7 0.5" class="DC_Taxel" />
                <inertial mass="1e-05" diaginertia="1e-06 1e-06 1e-06" pos="0 0 0" />
                <joint type="slide" stiffness="1000.0" damping="0.0001" axis="0 0 1" name="rffingertip_J_r0c2" range="-0.001 0.001" />
                <site name="rffingertip_S_r0c2" pos="0 0 0" class="D_Array" />
              </body>
              <body name="rffingertip_T_r0c3" pos="0.0045000000000000005 -0.0045000000000000005 0.0">
                <geom type="sphere" size="0.001" rgba="0.2 0.2 0.7 0.5" class="DC_Taxel" />
                <inertial mass="1e-05" diaginertia="1e-06 1e-06 1e-06" pos="0 0 0" />
                <joint type="slide" stiffness="1000.0" damping="0.0001" axis="0 0 1" name="rffingertip_J_r0c3" range="-0.001 0.001" />
                <site name="rffingertip_S_r0c3" pos="0 0 0" class="D_Array" />
              </body>
              <body name="rffingertip_T_r1c0" pos="-0.0045000000000000005 -0.0015000000000000005 0.0">
                <geom type="sphere" size="0.001" rgba="0.2 0.2 0.7 0.5" class="DC_Taxel" />
                <inertial mass="1e-05" diaginertia="1e-06 1e-06 1e-06" pos="0 0 0" />
                <joint type="slide" stiffness="1000.0" damping="0.0001" axis="0 0 1" name="rffingertip_J_r1c0" range="-0.001 0.001" />
                <site name="rffingertip_S_r1c0" pos="0 0 0" class="D_Array" />
              </body>
              <body name="rffingertip_T_r1c1" pos="-0.0015000000000000005 -0.0015000000000000005 0.0">
                <geom type="sphere" size="0.001" rgba="0.2 0.2 0.7 0.5" class="DC_Taxel" />
                <inertial mass="1e-05" diaginertia="1e-06 1e-06 1e-06" pos="0 0 0" />
                <joint type="slide" stiffness="1000.0" damping="0.0001" axis="0 0 1" name="rffingertip_J_r1c1" range="-0.001 0.001" />
                <site name="rffingertip_S_r1c1" pos="0 0 0" class="D_Array" />
              </body>
              <body name="rffingertip_T_r1c2" pos="0.0014999999999999996 -0.0015000000000000005 0.0">
                <geom type="sphere" size="0.001" rgba="0.2 0.2 0.7 0.5" class="DC_Taxel" />
                <inertial mass="1e-05" diaginertia="1e-06 1e-06 1e-06" pos="0 0 0" />
                <joint type="slide" stiffness="1000.0" damping="0.0001" axis="0 0 1" name="rffingertip_J_r1c2" range="-0.001 0.001" />
                <site name="rffingertip_S_r1c2" pos="0 0 0" class="D_Array" />
              </body>
              <body name="rffingertip_T_r1c3" pos="0.0045000000000000005 -0.0015000000000000005 0.0">
                <geom type="sphere" size="0.001" rgba="0.2 0.2 0.7 0.5" class="DC_Taxel" />
                <inertial mass="1e-05" diaginertia="1e-06 1e-06 1e-06" pos="0 0 0" />
                <joint type="slide" stiffness="1000.0" damping="0.0001" axis="0 0 1" name="rffingertip_J_r1c3" range="-0.001 0.001" />
                <site name="rffingertip_S_r1c3" pos="0 0 0" class="D_Array" />
              </body>
              <body name="rffingertip_T_r2c0" pos="-0.0045000000000000005 0.0014999999999999996 0.0">
                <geom type="sphere" size="0.001" rgba="0.2 0.2 0.7 0.5" class="DC_Taxel" />
                <inertial mass="1e-05" diaginertia="1e-06 1e-06 1e-06" pos="0 0 0" />
                <joint type="slide" stiffness="1000.0" damping="0.0001" axis="0 0 1" name="rffingertip_J_r2c0" range="-0.001 0.001" />
                <site name="rffingertip_S_r2c0" pos="0 0 0" class="D_Array" />
              </body>
              <body name="rffingertip_T_r2c1" pos="-0.0015000000000000005 0.0014999999999999996 0.0">
                <geom type="sphere" size="0.001" rgba="0.2 0.2 0.7 0.5" class="DC_Taxel" />
                <inertial mass="1e-05" diaginertia="1e-06 1e-06 1e-06" pos="0 0 0" />
                <joint type="slide" stiffness="1000.0" damping="0.0001" axis="0 0 1" name="rffingertip_J_r2c1" range="-0.001 0.001" />
                <site name="rffingertip_S_r2c1" pos="0 0 0" class="D_Array" />
              </body>
              <body name="rffingertip_T_r2c2" pos="0.0014999999999999996 0.0014999999999999996 0.0">
                <geom type="sphere" size="0.001" rgba="0.2 0.2 0.7 0.5" class="DC_Taxel" />
                <inertial mass="1e-05" diaginertia="1e-06 1e-06 1e-06" pos="0 0 0" />
                <joint type="slide" stiffness="1000.0" damping="0.0001" axis="0 0 1" name="rffingertip_J_r2c2" range="-0.001 0.001" />
                <site name="rffingertip_S_r2c2" pos="0 0 0" class="D_Array" />
              </body>
              <body name="rffingertip_T_r2c3" pos="0.0045000000000000005 0.0014999999999999996 0.0">
                <geom type="sphere" size="0.001" rgba="0.2 0.2 0.7 0.5" class="DC_Taxel" />
                <inertial mass="1e-05" diaginertia="1e-06 1e-06 1e-06" pos="0 0 0" />
                <joint type="slide" stiffness="1000.0" damping="0.0001" axis="0 0 1" name="rffingertip_J_r2c3" range="-0.001 0.001" />
                <site name="rffingertip_S_r2c3" pos="0 0 0" class="D_Array" />
              </body>
              <body name="rffingertip_T_r3c0" pos="-0.0045000000000000005 0.0045000000000000005 0.0">
                <geom type="sphere" size="0.001" rgba="0.2 0.2 0.7 0.5" class="DC_Taxel" />
                <inertial mass="1e-05" diaginertia="1e-06 1e-06 1e-06" pos="0 0 0" />
                <joint type="slide" stiffness="1000.0" damping="0.0001" axis="0 0 1" name="rffingertip_J_r3c0" range="-0.001 0.001" />
                <site name="rffingertip_S_r3c0" pos="0 0 0" class="D_Array" />
              </body>
              <body name="rffingertip_T_r3c1" pos="-0.0015000000000000005 0.0045000000000000005 0.0">
                <geom type="sphere" size="0.001" rgba="0.2 0.2 0.7 0.5" class="DC_Taxel" />
                <inertial mass="1e-05" diaginertia="1e-06 1e-06 1e-06" pos="0 0 0" />
                <joint type="slide" stiffness="1000.0" damping="0.0001" axis="0 0 1" name="rffingertip_J_r3c1" range="-0.001 0.001" />
                <site name="rffingertip_S_r3c1" pos="0 0 0" class="D_Array" />
              </body>
              <body name="rffingertip_T_r3c2" pos="0.0014999999999999996 0.0045000000000000005 0.0">
                <geom type="sphere" size="0.001" rgba="0.2 0.2 0.7 0.5" class="DC_Taxel" />
                <inertial mass="1e-05" diaginertia="1e-06 1e-06 1e-06" pos="0 0 0" />
                <joint type="slide" stiffness="1000.0" damping="0.0001" axis="0 0 1" name="rffingertip_J_r3c2" range="-0.001 0.001" />
                <site name="rffingertip_S_r3c2" pos="0 0 0" class="D_Array" />
              </body>
              <body name="rffingertip_T_r3c3" pos="0.0045000000000000005 0.0045000000000000005 0.0">
                <geom type="sphere" size="0.001" rgba="0.2 0.2 0.7 0.5" class="DC_Taxel" />
                <inertial mass="1e-05" diaginertia="1e-06 1e-06 1e-06" pos="0 0 0" />
                <joint type="slide" stiffness="1000.0" damping="0.0001" axis="0 0 1" name="rffingertip_J_r3c3" range="-0.001 0.001" />
                <site name="rffingertip_S_r3c3" pos="0 0 0" class="D_Array" />
              </body>
            </body>
          </body>
        </body>
      </body>
    </body>
    <body name="thpip0" pos="-0.0693952 -0.00124224 -0.0216224" quat="1 0 1 0">
      <inertial pos="0 0 0" quat="0.709913 0.704273 -0.000363156 0.00475427" mass="0.032" diaginertia="4.7981e-06 4.23406e-06 2.86184e-06" />
      <joint name="12" range="-0.349 2.094" actuatorfrcrange="-0.95 0.95" />
      <geom pos="-0.00535664 0.0003 0.000784034" quat="1 -1 -1 -1" mesh="pip" class="visual" />
      <geom pos="-0.00535664 0.0003 0.000784034" quat="1 -1 -1 -1" mesh="pip" class="collision" />
      <body name="thpip" pos="0 0.0143 -0.013" quat="1 1 -1 1">
        <inertial pos="0 0 0" mass="0.003" diaginertia="5.93e-07 5.49e-07 2.24e-07" />
        <joint name="13" range="-0.47 2.443" actuatorfrcrange="-0.95 0.95" />
        <geom pos="0.0119619 0 -0.0158526" quat="1 1 0 0" mesh="thumb_pip" class="visual" />
        <geom pos="0.0119619 0 -0.0158526" quat="1 1 0 0" mesh="thumb_pip" class="collision" />
        <body name="thdip" pos="0 0.0145 -0.017" quat="1 -1 0 0">
          <inertial pos="0 0 0" quat="0.708624 0.704906 0.00637342 0.0303153" mass="0.038" diaginertia="8.48742e-06 7.67823e-06 3.82835e-06" />
          <joint name="14" range="-1.2 1.9" actuatorfrcrange="-0.95 0.95" />
          <geom pos="0.0439687 0.057953 -0.00862868" quat="1 0 0 0" mesh="thumb_dip" class="visual" />
          <geom pos="0.0439687 0.057953 -0.00862868" quat="1 0 0 0" mesh="thumb_dip" class="collision" />
          <body name="thfingertip" pos="0 0.0466 0.0002" quat="0 0 0 1">
            <inertial pos="0 0 0" quat="0.704307 0.709299 0.006848 -0.0282727" mass="0.049" diaginertia="2.03882e-05 1.98443e-05 4.32049e-06" />
            <joint name="15" range="-1.34 1.88" actuatorfrcrange="-0.95 0.95" />
            <geom pos="0.0625595 0.0784597 0.0489929" quat="1 0 0 0" mesh="thumb_fingertip" class="visual" />
            <geom pos="0.0625595 0.0784597 0.0489929" quat="1 0 0 0" mesh="thumb_fingertip" class="collision" />
            <body name="thfingertip_panel_base" pos="-0.0123 -0.045 -0.0147" quat="0.70710678 0.0 0.70710678 0.0">
              <body name="thfingertip_T_r0c0" pos="-0.0045000000000000005 -0.0045000000000000005 0.0">
                <geom type="sphere" size="0.001" rgba="0.2 0.2 0.7 0.5" class="DC_Taxel" />
                <inertial mass="1e-05" diaginertia="1e-06 1e-06 1e-06" pos="0 0 0" />
                <joint type="slide" stiffness="1000.0" damping="0.0001" axis="0 0 1" name="thfingertip_J_r0c0" range="-0.001 0.001" />
                <site name="thfingertip_S_r0c0" pos="0 0 0" class="D_Array" />
              </body>
              <body name="thfingertip_T_r0c1" pos="-0.0015000000000000005 -0.0045000000000000005 0.0">
                <geom type="sphere" size="0.001" rgba="0.2 0.2 0.7 0.5" class="DC_Taxel" />
                <inertial mass="1e-05" diaginertia="1e-06 1e-06 1e-06" pos="0 0 0" />
                <joint type="slide" stiffness="1000.0" damping="0.0001" axis="0 0 1" name="thfingertip_J_r0c1" range="-0.001 0.001" />
                <site name="thfingertip_S_r0c1" pos="0 0 0" class="D_Array" />
              </body>
              <body name="thfingertip_T_r0c2" pos="0.0014999999999999996 -0.0045000000000000005 0.0">
                <geom type="sphere" size="0.001" rgba="0.2 0.2 0.7 0.5" class="DC_Taxel" />
                <inertial mass="1e-05" diaginertia="1e-06 1e-06 1e-06" pos="0 0 0" />
                <joint type="slide" stiffness="1000.0" damping="0.0001" axis="0 0 1" name="thfingertip_J_r0c2" range="-0.001 0.001" />
                <site name="thfingertip_S_r0c2" pos="0 0 0" class="D_Array" />
              </body>
              <body name="thfingertip_T_r0c3" pos="0.0045000000000000005 -0.0045000000000000005 0.0">
                <geom type="sphere" size="0.001" rgba="0.2 0.2 0.7 0.5" class="DC_Taxel" />
                <inertial mass="1e-05" diaginertia="1e-06 1e-06 1e-06" pos="0 0 0" />
                <joint type="slide" stiffness="1000.0" damping="0.0001" axis="0 0 1" name="thfingertip_J_r0c3" range="-0.001 0.001" />
                <site name="thfingertip_S_r0c3" pos="0 0 0" class="D_Array" />
              </body>
              <body name="thfingertip_T_r1c0" pos="-0.0045000000000000005 -0.0015000000000000005 0.0">
                <geom type="sphere" size="0.001" rgba="0.2 0.2 0.7 0.5" class="DC_Taxel" />
                <inertial mass="1e-05" diaginertia="1e-06 1e-06 1e-06" pos="0 0 0" />
                <joint type="slide" stiffness="1000.0" damping="0.0001" axis="0 0 1" name="thfingertip_J_r1c0" range="-0.001 0.001" />
                <site name="thfingertip_S_r1c0" pos="0 0 0" class="D_Array" />
              </body>
              <body name="thfingertip_T_r1c1" pos="-0.0015000000000000005 -0.0015000000000000005 0.0">
                <geom type="sphere" size="0.001" rgba="0.2 0.2 0.7 0.5" class="DC_Taxel" />
                <inertial mass="1e-05" diaginertia="1e-06 1e-06 1e-06" pos="0 0 0" />
                <joint type="slide" stiffness="1000.0" damping="0.0001" axis="0 0 1" name="thfingertip_J_r1c1" range="-0.001 0.001" />
                <site name="thfingertip_S_r1c1" pos="0 0 0" class="D_Array" />
              </body>
              <body name="thfingertip_T_r1c2" pos="0.0014999999999999996 -0.0015000000000000005 0.0">
                <geom type="sphere" size="0.001" rgba="0.2 0.2 0.7 0.5" class="DC_Taxel" />
                <inertial mass="1e-05" diaginertia="1e-06 1e-06 1e-06" pos="0 0 0" />
                <joint type="slide" stiffness="1000.0" damping="0.0001" axis="0 0 1" name="thfingertip_J_r1c2" range="-0.001 0.001" />
                <site name="thfingertip_S_r1c2" pos="0 0 0" class="D_Array" />
              </body>
              <body name="thfingertip_T_r1c3" pos="0.0045000000000000005 -0.0015000000000000005 0.0">
                <geom type="sphere" size="0.001" rgba="0.2 0.2 0.7 0.5" class="DC_Taxel" />
                <inertial mass="1e-05" diaginertia="1e-06 1e-06 1e-06" pos="0 0 0" />
                <joint type="slide" stiffness="1000.0" damping="0.0001" axis="0 0 1" name="thfingertip_J_r1c3" range="-0.001 0.001" />
                <site name="thfingertip_S_r1c3" pos="0 0 0" class="D_Array" />
              </body>
              <body name="thfingertip_T_r2c0" pos="-0.0045000000000000005 0.0014999999999999996 0.0">
                <geom type="sphere" size="0.001" rgba="0.2 0.2 0.7 0.5" class="DC_Taxel" />
                <inertial mass="1e-05" diaginertia="1e-06 1e-06 1e-06" pos="0 0 0" />
                <joint type="slide" stiffness="1000.0" damping="0.0001" axis="0 0 1" name="thfingertip_J_r2c0" range="-0.001 0.001" />
                <site name="thfingertip_S_r2c0" pos="0 0 0" class="D_Array" />
              </body>
              <body name="thfingertip_T_r2c1" pos="-0.0015000000000000005 0.0014999999999999996 0.0">
                <geom type="sphere" size="0.001" rgba="0.2 0.2 0.7 0.5" class="DC_Taxel" />
                <inertial mass="1e-05" diaginertia="1e-06 1e-06 1e-06" pos="0 0 0" />
                <joint type="slide" stiffness="1000.0" damping="0.0001" axis="0 0 1" name="thfingertip_J_r2c1" range="-0.001 0.001" />
                <site name="thfingertip_S_r2c1" pos="0 0 0" class="D_Array" />
              </body>
              <body name="thfingertip_T_r2c2" pos="0.0014999999999999996 0.0014999999999999996 0.0">
                <geom type="sphere" size="0.001" rgba="0.2 0.2 0.7 0.5" class="DC_Taxel" />
                <inertial mass="1e-05" diaginertia="1e-06 1e-06 1e-06" pos="0 0 0" />
                <joint type="slide" stiffness="1000.0" damping="0.0001" axis="0 0 1" name="thfingertip_J_r2c2" range="-0.001 0.001" />
                <site name="thfingertip_S_r2c2" pos="0 0 0" class="D_Array" />
              </body>
              <body name="thfingertip_T_r2c3" pos="0.0045000000000000005 0.0014999999999999996 0.0">
                <geom type="sphere" size="0.001" rgba="0.2 0.2 0.7 0.5" class="DC_Taxel" />
                <inertial mass="1e-05" diaginertia="1e-06 1e-06 1e-06" pos="0 0 0" />
                <joint type="slide" stiffness="1000.0" damping="0.0001" axis="0 0 1" name="thfingertip_J_r2c3" range="-0.001 0.001" />
                <site name="thfingertip_S_r2c3" pos="0 0 0" class="D_Array" />
              </body>
              <body name="thfingertip_T_r3c0" pos="-0.0045000000000000005 0.0045000000000000005 0.0">
                <geom type="sphere" size="0.001" rgba="0.2 0.2 0.7 0.5" class="DC_Taxel" />
                <inertial mass="1e-05" diaginertia="1e-06 1e-06 1e-06" pos="0 0 0" />
                <joint type="slide" stiffness="1000.0" damping="0.0001" axis="0 0 1" name="thfingertip_J_r3c0" range="-0.001 0.001" />
                <site name="thfingertip_S_r3c0" pos="0 0 0" class="D_Array" />
              </body>
              <body name="thfingertip_T_r3c1" pos="-0.0015000000000000005 0.0045000000000000005 0.0">
                <geom type="sphere" size="0.001" rgba="0.2 0.2 0.7 0.5" class="DC_Taxel" />
                <inertial mass="1e-05" diaginertia="1e-06 1e-06 1e-06" pos="0 0 0" />
                <joint type="slide" stiffness="1000.0" damping="0.0001" axis="0 0 1" name="thfingertip_J_r3c1" range="-0.001 0.001" />
                <site name="thfingertip_S_r3c1" pos="0 0 0" class="D_Array" />
              </body>
              <body name="thfingertip_T_r3c2" pos="0.0014999999999999996 0.0045000000000000005 0.0">
                <geom type="sphere" size="0.001" rgba="0.2 0.2 0.7 0.5" class="DC_Taxel" />
                <inertial mass="1e-05" diaginertia="1e-06 1e-06 1e-06" pos="0 0 0" />
                <joint type="slide" stiffness="1000.0" damping="0.0001" axis="0 0 1" name="thfingertip_J_r3c2" range="-0.001 0.001" />
                <site name="thfingertip_S_r3c2" pos="0 0 0" class="D_Array" />
              </body>
              <body name="thfingertip_T_r3c3" pos="0.0045000000000000005 0.0045000000000000005 0.0">
                <geom type="sphere" size="0.001" rgba="0.2 0.2 0.7 0.5" class="DC_Taxel" />
                <inertial mass="1e-05" diaginertia="1e-06 1e-06 1e-06" pos="0 0 0" />
                <joint type="slide" stiffness="1000.0" damping="0.0001" axis="0 0 1" name="thfingertip_J_r3c3" range="-0.001 0.001" />
                <site name="thfingertip_S_r3c3" pos="0 0 0" class="D_Array" />
              </body>
            </body>
          </body>
        </body>
      </body>
    </body>
  </body>

</mujocoinclude>